[2024-08-19T14:41:39.649+0000] {local_task_job_runner.py:120} INFO - ::group::Pre task execution logs
[2024-08-19T14:41:39.692+0000] {taskinstance.py:2076} INFO - Dependencies all met for dep_context=non-requeueable deps ti=<TaskInstance: trino_query_dag.insert_data_inc manual__2024-08-19T14:38:47.720219+00:00 [queued]>
[2024-08-19T14:41:39.705+0000] {taskinstance.py:2076} INFO - Dependencies all met for dep_context=requeueable deps ti=<TaskInstance: trino_query_dag.insert_data_inc manual__2024-08-19T14:38:47.720219+00:00 [queued]>
[2024-08-19T14:41:39.706+0000] {taskinstance.py:2306} INFO - Starting attempt 3 of 4
[2024-08-19T14:41:39.722+0000] {taskinstance.py:2330} INFO - Executing <Task(TrinoOperator): insert_data_inc> on 2024-08-19 14:38:47.720219+00:00
[2024-08-19T14:41:39.730+0000] {logging_mixin.py:188} WARNING - /home/airflow/.local/lib/python3.12/site-packages/airflow/task/task_runner/standard_task_runner.py:62 DeprecationWarning: This process (pid=427) is multi-threaded, use of fork() may lead to deadlocks in the child.
[2024-08-19T14:41:39.731+0000] {standard_task_runner.py:64} INFO - Started process 428 to run task
[2024-08-19T14:41:39.730+0000] {standard_task_runner.py:90} INFO - Running: ['airflow', 'tasks', 'run', 'trino_query_dag', 'insert_data_inc', 'manual__2024-08-19T14:38:47.720219+00:00', '--job-id', '31', '--raw', '--subdir', 'DAGS_FOLDER/test.py', '--cfg-path', '/tmp/tmpgjnx307g']
[2024-08-19T14:41:39.732+0000] {standard_task_runner.py:91} INFO - Job 31: Subtask insert_data_inc
[2024-08-19T14:41:39.753+0000] {logging_mixin.py:188} WARNING - /home/airflow/.local/lib/python3.12/site-packages/airflow/settings.py:195 DeprecationWarning: The sql_alchemy_conn option in [core] has been moved to the sql_alchemy_conn option in [database] - the old setting has been used, but please update your config.
[2024-08-19T14:41:39.792+0000] {task_command.py:426} INFO - Running <TaskInstance: trino_query_dag.insert_data_inc manual__2024-08-19T14:38:47.720219+00:00 [running]> on host b476143e3d64
[2024-08-19T14:41:39.895+0000] {taskinstance.py:2648} INFO - Exporting env vars: AIRFLOW_CTX_DAG_OWNER='airflow' AIRFLOW_CTX_DAG_ID='trino_query_dag' AIRFLOW_CTX_TASK_ID='insert_data_inc' AIRFLOW_CTX_EXECUTION_DATE='2024-08-19T14:38:47.720219+00:00' AIRFLOW_CTX_TRY_NUMBER='3' AIRFLOW_CTX_DAG_RUN_ID='manual__2024-08-19T14:38:47.720219+00:00'
[2024-08-19T14:41:39.896+0000] {taskinstance.py:430} INFO - ::endgroup::
[2024-08-19T14:41:39.912+0000] {sql.py:282} INFO - Executing: insert into  hive.iris.traffic_crashes SELECT crash_date FROM oracle.test.traffic_crashes WHERE crash_date = '2023-07-13'
[2024-08-19T14:41:39.930+0000] {base.py:84} INFO - Using connection ID 'my_trino_connection' for task execution.
[2024-08-19T14:41:39.942+0000] {base.py:84} INFO - Using connection ID 'my_trino_connection' for task execution.
[2024-08-19T14:41:39.952+0000] {base.py:84} INFO - Using connection ID 'my_trino_connection' for task execution.
[2024-08-19T14:41:39.956+0000] {taskinstance.py:441} INFO - ::group::Post task execution logs
[2024-08-19T14:41:39.957+0000] {taskinstance.py:2905} ERROR - Task failed with exception
Traceback (most recent call last):
  File "/home/airflow/.local/lib/python3.12/site-packages/airflow/models/taskinstance.py", line 465, in _execute_task
    result = _execute_callable(context=context, **execute_callable_kwargs)
             ^^^^^^^^^^^^^^^^^^^^^^^^^^^^^^^^^^^^^^^^^^^^^^^^^^^^^^^^^^^^^
  File "/home/airflow/.local/lib/python3.12/site-packages/airflow/models/taskinstance.py", line 432, in _execute_callable
    return execute_callable(context=context, **execute_callable_kwargs)
           ^^^^^^^^^^^^^^^^^^^^^^^^^^^^^^^^^^^^^^^^^^^^^^^^^^^^^^^^^^^^
  File "/home/airflow/.local/lib/python3.12/site-packages/airflow/models/baseoperator.py", line 401, in wrapper
    return func(self, *args, **kwargs)
           ^^^^^^^^^^^^^^^^^^^^^^^^^^^
  File "/home/airflow/.local/lib/python3.12/site-packages/airflow/providers/common/sql/operators/sql.py", line 288, in execute
    output = hook.run(
             ^^^^^^^^^
  File "/home/airflow/.local/lib/python3.12/site-packages/airflow/providers/common/sql/hooks/sql.py", line 439, in run
    with closing(conn.cursor()) as cur:
                 ^^^^^^^^^^^^^
  File "/home/airflow/.local/lib/python3.12/site-packages/trino/dbapi.py", line 264, in cursor
    request = self._create_request()
              ^^^^^^^^^^^^^^^^^^^^^^
  File "/home/airflow/.local/lib/python3.12/site-packages/trino/dbapi.py", line 245, in _create_request
    return trino.client.TrinoRequest(
           ^^^^^^^^^^^^^^^^^^^^^^^^^^
  File "/home/airflow/.local/lib/python3.12/site-packages/trino/client.py", line 434, in __init__
    raise ValueError("cannot use authentication with HTTP")
ValueError: cannot use authentication with HTTP
[2024-08-19T14:41:39.968+0000] {taskinstance.py:1206} INFO - Marking task as UP_FOR_RETRY. dag_id=trino_query_dag, task_id=insert_data_inc, run_id=manual__2024-08-19T14:38:47.720219+00:00, execution_date=20240819T143847, start_date=20240819T144139, end_date=20240819T144139
[2024-08-19T14:41:39.986+0000] {standard_task_runner.py:110} ERROR - Failed to execute job 31 for task insert_data_inc (cannot use authentication with HTTP; 428)
[2024-08-19T14:41:40.027+0000] {local_task_job_runner.py:243} INFO - Task exited with return code 1
[2024-08-19T14:41:40.044+0000] {logging_mixin.py:188} WARNING - /home/airflow/.local/lib/python3.12/site-packages/airflow/models/baseoperator.py:1297 AirflowProviderDeprecationWarning: Call to deprecated class TrinoOperator. (Please use `airflow.providers.common.sql.operators.sql.SQLExecuteQueryOperator`.)
[2024-08-19T14:41:40.063+0000] {taskinstance.py:3503} INFO - 0 downstream tasks scheduled from follow-on schedule check
[2024-08-19T14:41:40.066+0000] {local_task_job_runner.py:222} INFO - ::endgroup::
